Workbook

Sheet Dashboard
C3: [RNF Dash Board]
C6: # 월별 매출액 | F6: 최근 1년 | K6: # 고객별 매출추이
F7: 매출처(수) | G7: 매출 | H7: 매출원가 | I7: 수익 (E)
F8: =AVERAGE(F11:F22) -> 5.4166667 | G8: =SUM(G11:G22) -> 279393587 | H8: =SUM(H11:H22) -> 210944426 | I8: =SUM(I11:I22) -> 68449161 | K8: 고객명 | L8: 월 | M8: 매출
C9: [전체 매출] | K9: 현대지게차경기북부판매(주) | L9: 2025년2월 | M9: =SUMIFS( RAW!$N$3:$N$999, RAW!$G$3:$G$999, $K$9, RAW!$F$3:$F$999, L9 ) -> 0
C10: 년 | D10: 월 | E10: 년월 | F10: 매출처 (수) | G10: 매출 | H10: 매출원가 | I10: 수익 (E) | L10: 2025년3월 | M10: =SUMIFS( RAW!$N$3:$N$999, RAW!$G$3:$G$999, $K$9, RAW!$F$3:$F$999, L10 ) -> 0
C11: 2025년 | D11: 4월 | E11: =CONCATENATE(C11,D11) -> 2025년4월 | F11: {=COUNTA(_xlfn.UNIQUE(_xlfn._xlws.FILTER(RAW!$G$4:$G$1000,(RAW!$F$4:$F$1000=E11) * (RAW!$G$4:$G$1000<>""))))} -> 4 | G11: =SUMIF(RAW!F:F,Dashboard!E11,RAW!N:N) -> 7491000 | H11: =SUMIF(RAW!F:F,Dashboard!E11,RAW!P:P) -> 6485600 | I11: =G11-H11 -> 1005400 | L11: 2025년4월 | M11: =SUMIFS( RAW!$N$3:$N$999, RAW!$G$3:$G$999, $K$9, RAW!$F$3:$F$999, L11 ) -> 0
C12: 2025년 | D12: 5월 | E12: =CONCATENATE(C12,D12) -> 2025년5월 | F12: {=COUNTA(_xlfn.UNIQUE(_xlfn._xlws.FILTER(RAW!$G$4:$G$1000,(RAW!$F$4:$F$1000=E12) * (RAW!$G$4:$G$1000<>""))))} -> 9 | G12: =SUMIF(RAW!F:F,Dashboard!E12,RAW!N:N) -> 94519040 | H12: =SUMIF(RAW!F:F,Dashboard!E12,RAW!P:P) -> 74413108 | I12: =G12-H12 -> 20105932 | L12: 2025년5월 | M12: =SUMIFS( RAW!$N$3:$N$999, RAW!$G$3:$G$999, $K$9, RAW!$F$3:$F$999, L12 ) -> 5610000
C13: 2025년 | D13: 6월 | E13: =CONCATENATE(C13,D13) -> 2025년6월 | F13: {=COUNTA(_xlfn.UNIQUE(_xlfn._xlws.FILTER(RAW!$G$4:$G$1000,(RAW!$F$4:$F$1000=E13) * (RAW!$G$4:$G$1000<>""))))} -> 9 | G13: =SUMIF(RAW!F:F,Dashboard!E13,RAW!N:N) -> 40979147 | H13: =SUMIF(RAW!F:F,Dashboard!E13,RAW!P:P) -> 20553918 | I13: =G13-H13 -> 20425229 | L13: 2025년6월 | M13: =SUMIFS( RAW!$N$3:$N$999, RAW!$G$3:$G$999, $K$9, RAW!$F$3:$F$999, L13 ) -> 3388000
C14: 2025년 | D14: 7월 | E14: =CONCATENATE(C14,D14) -> 2025년7월 | F14: {=COUNTA(_xlfn.UNIQUE(_xlfn._xlws.FILTER(RAW!$G$4:$G$1000,(RAW!$F$4:$F$1000=E14) * (RAW!$G$4:$G$1000<>""))))} -> 5 | G14: =SUMIF(RAW!F:F,Dashboard!E14,RAW!N:N) -> 16948800 | H14: =SUMIF(RAW!F:F,Dashboard!E14,RAW!P:P) -> 14938000 | I14: =G14-H14 -> 2010800 | L14: 2025년7월 | M14: =SUMIFS( RAW!$N$3:$N$999, RAW!$G$3:$G$999, $K$9, RAW!$F$3:$F$999, L14 ) -> 4584800
C15: 2025년 | D15: 8월 | E15: =CONCATENATE(C15,D15) -> 2025년8월 | F15: {=COUNTA(_xlfn.UNIQUE(_xlfn._xlws.FILTER(RAW!$G$4:$G$1000,(RAW!$F$4:$F$1000=E15) * (RAW!$G$4:$G$1000<>""))))} -> 4 | G15: =SUMIF(RAW!F:F,Dashboard!E15,RAW!N:N) -> 13255000 | H15: =SUMIF(RAW!F:F,Dashboard!E15,RAW!P:P) -> 11396000 | I15: =G15-H15 -> 1859000 | L15: 2025년8월 | M15: =SUMIFS( RAW!$N$3:$N$999, RAW!$G$3:$G$999, $K$9, RAW!$F$3:$F$999, L15 ) -> 3179000
C16: 2025년 | D16: 9월 | E16: =CONCATENATE(C16,D16) -> 2025년9월 | F16: {=COUNTA(_xlfn.UNIQUE(_xlfn._xlws.FILTER(RAW!$G$4:$G$1000,(RAW!$F$4:$F$1000=E16) * (RAW!$G$4:$G$1000<>""))))} -> 6 | G16: =SUMIF(RAW!F:F,Dashboard!E16,RAW!N:N) -> 16970800 | H16: =SUMIF(RAW!F:F,Dashboard!E16,RAW!P:P) -> 15118400 | I16: =G16-H16 -> 1852400 | L16: 2025년9월 | M16: =SUMIFS( RAW!$N$3:$N$999, RAW!$G$3:$G$999, $K$9, RAW!$F$3:$F$999, L16 ) -> 1606000
C17: 2025년 | D17: 10월 | E17: =CONCATENATE(C17,D17) -> 2025년10월 | F17: {=COUNTA(_xlfn.UNIQUE(_xlfn._xlws.FILTER(RAW!$G$4:$G$1000,(RAW!$F$4:$F$1000=E17) * (RAW!$G$4:$G$1000<>""))))} -> 4 | G17: =SUMIF(RAW!F:F,Dashboard!E17,RAW!N:N) -> 7997000 | H17: =SUMIF(RAW!F:F,Dashboard!E17,RAW!P:P) -> 6589000 | I17: =G17-H17 -> 1408000 | L17: 2025년10월 | M17: =SUMIFS( RAW!$N$3:$N$999, RAW!$G$3:$G$999, $K$9, RAW!$F$3:$F$999, L17 ) -> 616000
C18: 2025년 | D18: 11월 | E18: =CONCATENATE(C18,D18) -> 2025년11월 | F18: {=COUNTA(_xlfn.UNIQUE(_xlfn._xlws.FILTER(RAW!$G$4:$G$1000,(RAW!$F$4:$F$1000=E18) * (RAW!$G$4:$G$1000<>""))))} -> 7 | G18: =SUMIF(RAW!F:F,Dashboard!E18,RAW!N:N) -> 53264200 | H18: =SUMIF(RAW!F:F,Dashboard!E18,RAW!P:P) -> 38390000 | I18: =G18-H18 -> 14874200 | L18: 2025년11월 | M18: =SUMIFS( RAW!$N$3:$N$999, RAW!$G$3:$G$999, $K$9, RAW!$F$3:$F$999, L18 ) -> 5139200
C19: 2025년 | D19: 12월 | E19: =CONCATENATE(C19,D19) -> 2025년12월 | F19: {=COUNTA(_xlfn.UNIQUE(_xlfn._xlws.FILTER(RAW!$G$4:$G$1000,(RAW!$F$4:$F$1000=E19) * (RAW!$G$4:$G$1000<>""))))} -> 8 | G19: =SUMIF(RAW!F:F,Dashboard!E19,RAW!N:N) -> 18966200 | H19: =SUMIF(RAW!F:F,Dashboard!E19,RAW!P:P) -> 16205200 | I19: =G19-H19 -> 2761000 | L19: 2025년12월 | M19: =SUMIFS( RAW!$N$3:$N$999, RAW!$G$3:$G$999, $K$9, RAW!$F$3:$F$999, L19 ) -> 3179000
C20: 2026년 | D20: 1월 | E20: =CONCATENATE(C20,D20) -> 2026년1월 | F20: {=COUNTA(_xlfn.UNIQUE(_xlfn._xlws.FILTER(RAW!$G$4:$G$1000,(RAW!$F$4:$F$1000=E20) * (RAW!$G$4:$G$1000<>""))))} -> 7 | G20: =SUMIF(RAW!F:F,Dashboard!E20,RAW!N:N) -> 9002400 | H20: =SUMIF(RAW!F:F,Dashboard!E20,RAW!P:P) -> 6855200 | I20: =G20-H20 -> 2147200 | L20: 2026년1월 | M20: =SUMIFS( RAW!$N$3:$N$999, RAW!$G$3:$G$999, $K$9, RAW!$F$3:$F$999, L20 ) -> 0
C21: 2026년 | D21: 2월 | F21: {=COUNTA(_xlfn.UNIQUE(_xlfn._xlws.FILTER(RAW!$G$4:$G$1000,(RAW!$F$4:$F$1000=E21) * (RAW!$G$4:$G$1000<>""))))} -> 1 | G21: =SUMIF(RAW!F:F,Dashboard!E21,RAW!N:N) -> 0 | H21: =SUMIF(RAW!F:F,Dashboard!E21,RAW!P:P) -> 0 | I21: =G21-H21 -> 0
C22: 2026년 | D22: 3월 | F22: {=COUNTA(_xlfn.UNIQUE(_xlfn._xlws.FILTER(RAW!$G$4:$G$1000,(RAW!$F$4:$F$1000=E22) * (RAW!$G$4:$G$1000<>""))))} -> 1 | G22: =SUMIF(RAW!F:F,Dashboard!E22,RAW!N:N) -> 0 | H22: =SUMIF(RAW!F:F,Dashboard!E22,RAW!P:P) -> 0 | I22: =G22-H22 -> 0 | K22: # Top 5 (전체) | N22: # 매출비중
N23: {=_xlfn.UNIQUE(_xlfn._xlws.FILTER(RAW!I5:I1999, RAW!I5:I1999<>""))} -> 렌탈 | O23: =SUMIFS(RAW!N:N, RAW!I:I, N23) / SUM(RAW!N:N) -> 0.18060086 | P23: =SUMIFS(RAW!N:N, RAW!I:I,Dashboard!N23) -> 52613000
F24: 최근 1년 현황 | H24: 매출 | I24: =SUM(G27:G38)/10 -> 10590580 | K24: {=_xlfn.TAKE( _xlfn.SORTBY( _xlfn.UNIQUE(_xlfn._xlws.FILTER(RAW!G3:G999, RAW!G3:G999<>"")), _xlfn.BYROW( _xlfn.UNIQUE(_xlfn._xlws.FILTER(RAW!G3:G999, RAW!G3:G999<>"")), _xlfn.LAMBDA(_xlpm.c, SUMIFS(RAW!N3:N999, RAW!G3:G999, _xlpm.c)) ), -1 ), 5 )} -> 동성종합지게차 | L24: =SUMIFS(RAW!N:N,RAW!G:G,Dashboard!K24) -> 1.0038795e+08 | N24: 기타 | O24: =SUMIFS(RAW!N:N, RAW!I:I, N24) / SUM(RAW!N:N) -> 0.31906277 | P24: =SUMIFS(RAW!N:N, RAW!I:I,Dashboard!N24) -> 92950000
C25: [타이어 매출] | F25: 거래처 | G25: =SUM(F27:F36)/10 -> 3.7 | H25: 수익 | I25: =SUM(I26:I38)/10 -> 1250150 | K25: 주식회사 에스제이 | L25: =SUMIFS(RAW!N:N,RAW!G:G,Dashboard!K25) -> 43945000 | N25: 타이어 | O25: =SUMIFS(RAW!N:N, RAW!I:I, N25) / SUM(RAW!N:N) -> 0.36353521 | P25: =SUMIFS(RAW!N:N, RAW!I:I,Dashboard!N25) -> 105905800
C26: 년 | D26: 월 | E26: 년월 | F26: 매출처 (수) | G26: 매출 | H26: 매출원가 | I26: 수익 (E) | K26: 백호중기 | L26: =SUMIFS(RAW!N:N,RAW!G:G,Dashboard!K26) -> 33576400 | N26: LFP(지게차) | O26: =SUMIFS(RAW!N:N, RAW!I:I, N26) / SUM(RAW!N:N) -> 0.041913029 | P26: =SUMIFS(RAW!N:N, RAW!I:I,Dashboard!N26) -> 12210187
C27: 2025년 | D27: 4월 | E27: =CONCATENATE(C27,D27) -> 2025년4월 | F27: {=COUNTA(_xlfn.UNIQUE(_xlfn._xlws.FILTER(RAW!$G:$G,(RAW!$F:$F=E27)*(RAW!$I:$I="타이어"), "")))} -> 2 | G27: =SUMIFS(RAW!N:N,RAW!F:F,Dashboard!E27,RAW!I:I,"타이어") -> 5203000 | H27: =SUMIFS(RAW!P:P,RAW!F:F,Dashboard!E27,RAW!I:I,"타이어") -> 4747600 | I27: =G27-H27 -> 455400 | K27: 현대지게차경기북부판매(주) | L27: =SUMIFS(RAW!N:N,RAW!G:G,Dashboard!K27) -> 29282000 | N27: LFP(고소작업대) | O27: =SUMIFS(RAW!N:N, RAW!I:I, N27) / SUM(RAW!N:N) -> 0.094888135 | P27: =SUMIFS(RAW!N:N, RAW!I:I,Dashboard!N27) -> 27643000
C28: 2025년 | D28: 5월 | E28: =CONCATENATE(C28,D28) -> 2025년5월 | F28: {=COUNTA(_xlfn.UNIQUE(_xlfn._xlws.FILTER(RAW!$G:$G,(RAW!$F:$F=E28)*(RAW!$I:$I="타이어"), "")))} -> 5 | G28: =SUMIFS(RAW!N:N,RAW!F:F,Dashboard!E28,RAW!I:I,"타이어") -> 18400800 | H28: =SUMIFS(RAW!P:P,RAW!F:F,Dashboard!E28,RAW!I:I,"타이어") -> 15354900 | I28: =G28-H28 -> 3045900 | K28: 도화중기주식회사 | L28: =SUMIFS(RAW!N:N,RAW!G:G,Dashboard!K28) -> 21421400 | O28: =SUMIFS(RAW!N:N, RAW!I:I, N28) / SUM(RAW!N:N) -> 0 | P28: =SUMIFS(RAW!N:N, RAW!I:I,Dashboard!N28) -> 0
C29: 2025년 | D29: 6월 | E29: =CONCATENATE(C29,D29) -> 2025년6월 | F29: {=COUNTA(_xlfn.UNIQUE(_xlfn._xlws.FILTER(RAW!$G:$G,(RAW!$F:$F=E29)*(RAW!$I:$I="타이어"), "")))} -> 4 | G29: =SUMIFS(RAW!N:N,RAW!F:F,Dashboard!E29,RAW!I:I,"타이어") -> 8769200 | H29: =SUMIFS(RAW!P:P,RAW!F:F,Dashboard!E29,RAW!I:I,"타이어") -> 8261000 | I29: =G29-H29 -> 508200 | O29: =SUMIFS(RAW!N:N, RAW!I:I, N29) / SUM(RAW!N:N) -> 0 | P29: =SUMIFS(RAW!N:N, RAW!I:I,Dashboard!N29) -> 0
C30: 2025년 | D30: 7월 | E30: =CONCATENATE(C30,D30) -> 2025년7월 | F30: {=COUNTA(_xlfn.UNIQUE(_xlfn._xlws.FILTER(RAW!$G:$G,(RAW!$F:$F=E30)*(RAW!$I:$I="타이어"), "")))} -> 3 | G30: =SUMIFS(RAW!N:N,RAW!F:F,Dashboard!E30,RAW!I:I,"타이어") -> 12240800 | H30: =SUMIFS(RAW!P:P,RAW!F:F,Dashboard!E30,RAW!I:I,"타이어") -> 11440000 | I30: =G30-H30 -> 800800 | K30: # Top 5 (타이어)
C31: 2025년 | D31: 8월 | E31: =CONCATENATE(C31,D31) -> 2025년8월 | F31: {=COUNTA(_xlfn.UNIQUE(_xlfn._xlws.FILTER(RAW!$G:$G,(RAW!$F:$F=E31)*(RAW!$I:$I="타이어"), "")))} -> 2 | G31: =SUMIFS(RAW!N:N,RAW!F:F,Dashboard!E31,RAW!I:I,"타이어") -> 8547000 | H31: =SUMIFS(RAW!P:P,RAW!F:F,Dashboard!E31,RAW!I:I,"타이어") -> 7898000 | I31: =G31-H31 -> 649000
C32: 2025년 | D32: 9월 | E32: =CONCATENATE(C32,D32) -> 2025년9월 | F32: {=COUNTA(_xlfn.UNIQUE(_xlfn._xlws.FILTER(RAW!$G:$G,(RAW!$F:$F=E32)*(RAW!$I:$I="타이어"), "")))} -> 4 | G32: =SUMIFS(RAW!N:N,RAW!F:F,Dashboard!E32,RAW!I:I,"타이어") -> 12262800 | H32: =SUMIFS(RAW!P:P,RAW!F:F,Dashboard!E32,RAW!I:I,"타이어") -> 11620400 | I32: =G32-H32 -> 642400 | K32: {=_xlfn.TAKE( _xlfn.SORTBY( _xlfn.UNIQUE(_xlfn._xlws.FILTER(RAW!$G$3:$G$999, RAW!$G$3:$G$999<>"")), _xlfn.BYROW( _xlfn.UNIQUE(_xlfn._xlws.FILTER(RAW!$G$3:$G$999, RAW!$G$3:$G$999<>"")), _xlfn.LAMBDA(_xlpm.c, SUMIFS(RAW!$N$3:$N$999, RAW!$G$3:$G$999, _xlpm.c, RAW!$I$3:$I$999, "타이어")) ), -1 ), 5 )} -> 백호중기 | L32: =SUMIFS(RAW!N:N,RAW!G:G,Dashboard!K32,RAW!I:I,"타이어") -> 33576400
C33: 2025년 | D33: 10월 | E33: =CONCATENATE(C33,D33) -> 2025년10월 | F33: {=COUNTA(_xlfn.UNIQUE(_xlfn._xlws.FILTER(RAW!$G:$G,(RAW!$F:$F=E33)*(RAW!$I:$I="타이어"), "")))} -> 2 | G33: =SUMIFS(RAW!N:N,RAW!F:F,Dashboard!E33,RAW!I:I,"타이어") -> 3289000 | H33: =SUMIFS(RAW!P:P,RAW!F:F,Dashboard!E33,RAW!I:I,"타이어") -> 3091000 | I33: =G33-H33 -> 198000 | K33: 현대지게차경기북부판매(주) | L33: =SUMIFS(RAW!N:N,RAW!G:G,Dashboard!K33,RAW!I:I,"타이어") -> 22682000
C34: 2025년 | D34: 11월 | E34: =CONCATENATE(C34,D34) -> 2025년11월 | F34: {=COUNTA(_xlfn.UNIQUE(_xlfn._xlws.FILTER(RAW!$G:$G,(RAW!$F:$F=E34)*(RAW!$I:$I="타이어"), "")))} -> 4 | G34: =SUMIFS(RAW!N:N,RAW!F:F,Dashboard!E34,RAW!I:I,"타이어") -> 15413200 | H34: =SUMIFS(RAW!P:P,RAW!F:F,Dashboard!E34,RAW!I:I,"타이어") -> 13695000 | I34: =G34-H34 -> 1718200 | K34: 도화중기주식회사 | L34: =SUMIFS(RAW!N:N,RAW!G:G,Dashboard!K34,RAW!I:I,"타이어") -> 21421400
C35: 2025년 | D35: 12월 | E35: =CONCATENATE(C35,D35) -> 2025년12월 | F35: {=COUNTA(_xlfn.UNIQUE(_xlfn._xlws.FILTER(RAW!$G:$G,(RAW!$F:$F=E35)*(RAW!$I:$I="타이어"), "")))} -> 6 | G35: =SUMIFS(RAW!N:N,RAW!F:F,Dashboard!E35,RAW!I:I,"타이어") -> 14258200 | H35: =SUMIFS(RAW!P:P,RAW!F:F,Dashboard!E35,RAW!I:I,"타이어") -> 12707200 | I35: =G35-H35 -> 1551000 | K35: 대양토탈라인 주식회사 | L35: =SUMIFS(RAW!N:N,RAW!G:G,Dashboard!K35,RAW!I:I,"타이어") -> 10835000
C36: 2026년 | D36: 1월 | E36: =CONCATENATE(C36,D36) -> 2026년1월 | F36: {=COUNTA(_xlfn.UNIQUE(_xlfn._xlws.FILTER(RAW!$G:$G,(RAW!$F:$F=E36)*(RAW!$I:$I="타이어"), "")))} -> 5 | G36: =SUMIFS(RAW!N:N,RAW!F:F,Dashboard!E36,RAW!I:I,"타이어") -> 4294400 | H36: =SUMIFS(RAW!P:P,RAW!F:F,Dashboard!E36,RAW!I:I,"타이어") -> 3357200 | I36: =G36-H36 -> 937200 | K36: 상주대형중기화물 | L36: =SUMIFS(RAW!N:N,RAW!G:G,Dashboard!K36,RAW!I:I,"타이어") -> 4699200
C37: 2026년 | D37: 2월 | E37: =CONCATENATE(C37,D37) -> 2026년2월 | F37: {=COUNTA(_xlfn.UNIQUE(_xlfn._xlws.FILTER(RAW!$G:$G,(RAW!$F:$F=E37)*(RAW!$I:$I="타이어"), "")))} -> 2 | G37: =SUMIFS(RAW!N:N,RAW!F:F,Dashboard!E37,RAW!I:I,"타이어") -> 1247400 | H37: =SUMIFS(RAW!P:P,RAW!F:F,Dashboard!E37,RAW!I:I,"타이어") -> 1232000 | I37: =G37-H37 -> 15400
C38: 2026년 | D38: 3월 | E38: =CONCATENATE(C38,D38) -> 2026년3월 | F38: {=COUNTA(_xlfn.UNIQUE(_xlfn._xlws.FILTER(RAW!$G:$G,(RAW!$F:$F=E38)*(RAW!$I:$I="타이어"), "")))} -> 1 | G38: =SUMIFS(RAW!N:N,RAW!F:F,Dashboard!E38,RAW!I:I,"타이어") -> 1980000 | H38: =SUMIFS(RAW!P:P,RAW!F:F,Dashboard!E38,RAW!I:I,"타이어") -> 0 | I38: =G38-H38 -> 1980000

Sheet RAW
B4: 순번 | C4: 날짜 | D4: 년 | E4: 월 | F4: 년월 | G4: 고객명 | H4: 사업자번호 | I4: 종류 | J4: Maker | K4: 규격 | L4: 수량 | M4: 판매단가 | N4: 총매출 | O4: 매입단가 | P4: 총매입 | Q4: Margin | R4: 계산서 | S4: 입금 | T4: 배송일자 | U4: 배송확인 | V4: 휠반납 확인 | W4: Closing | X4: 비고
B5: 1 | C5: 45720 | D5: =IF((C5=""),"",(YEAR(C5)&"년")) -> 2025년 | E5: =IF((C5=""),"",(MONTH(C5)&"월")) -> 3월 | F5: =CONCATENATE(D5,E5) -> 2025년3월 | G5: 주식회사 에스제이 | H5: =IFERROR((VLOOKUP(G5,Backdata!G:H,2,0)),"") -> 235-86-01235 | I5: 렌탈 | J5: 두산 | K5: 4.5톤 | L5: 1 | M5: 1450000 | N5: =M5*L5*1.1 -> 1595000 | O5: 1000000 | P5: =O5*L5*1.1 -> 1100000 | Q5: =N5-P5 -> 495000 | R5: O | T5: =IF(OR(I5="타이어",I5=""),"",C5) -> 45720 | U5: =IF(T5="","","완료") -> 완료
B6: =B5+1 -> 2 | C6: 45733 | D6: =IF((C6=""),"",(YEAR(C6)&"년")) -> 2025년 | E6: =IF((C6=""),"",(MONTH(C6)&"월")) -> 3월 | F6: =CONCATENATE(D6,E6) -> 2025년3월 | G6: 코오롱글로벌(주)상사부문 | H6: =IFERROR((VLOOKUP(G6,Backdata!G:H,2,0)),"") -> 119-85-35038 | I6: 기타 | J6: BYD | K6: 3톤 | L6: 1 | M6: 3000000 | N6: =M6*L6*1.1 -> 3300000 | P6: =O6*L6*1.1 -> 0 | Q6: =N6-P6 -> 3300000 | R6: O | T6: =IF(OR(I6="타이어",I6=""),"",C6) -> 45733 | U6: =IF(T6="","","완료") -> 완료
B7: =B6+1 -> 3 | C7: 45749 | D7: =IF((C7=""),"",(YEAR(C7)&"년")) -> 2025년 | E7: =IF((C7=""),"",(MONTH(C7)&"월")) -> 4월 | F7: =CONCATENATE(D7,E7) -> 2025년4월 | G7: 도화중기주식회사 | H7: =IFERROR((VLOOKUP(G7,Backdata!G:H,2,0)),"") -> 301-86-32786 | I7: 타이어 | J7: MAXAM | K7: 815-15 | L7: 2 | M7: 323000 | N7: =M7*L7*1.1 -> 710600 | O7: 270000 | P7: =O7*L7*1.1 -> 594000 | Q7: =N7-P7 -> 116600 | R7: O | T7: =IF(OR(I7="타이어",I7=""),"",C7) | U7: =IF(T7="","","완료")
B8: =B7+1 -> 4 | C8: 45751 | D8: =IF((C8=""),"",(YEAR(C8)&"년")) -> 2025년 | E8: =IF((C8=""),"",(MONTH(C8)&"월")) -> 4월 | F8: =CONCATENATE(D8,E8) -> 2025년4월 | G8: 주식회사 에스제이 | H8: =IFERROR((VLOOKUP(G8,Backdata!G:H,2,0)),"") -> 235-86-01235 | I8: 렌탈 | J8: 두산 | K8: 4.5톤 | L8: 1 | M8: 1450000 | N8: =M8*L8*1.1 -> 1595000 | O8: 1000000 | P8: =O8*L8*1.1 -> 1100000 | Q8: =N8-P8 -> 495000 | R8: O | T8: =IF(OR(I8="타이어",I8=""),"",C8) -> 45751 | U8: =IF(T8="","","완료") -> 완료
B9: =B8+1 -> 5 | C9: 45756 | D9: =IF((C9=""),"",(YEAR(C9)&"년")) -> 2025년 | E9: =IF((C9=""),"",(MONTH(C9)&"월")) -> 4월 | F9: =CONCATENATE(D9,E9) -> 2025년4월 | G9: 도화중기주식회사 | H9: =IFERROR((VLOOKUP(G9,Backdata!G:H,2,0)),"") -> 301-86-32786 | I9: 타이어 | J9: 흥아 | K9: 825-15 | L9: 6 | M9: 210000 | N9: =M9*L9*1.1 -> 1386000 | O9: 210000 | P9: =O9*L9*1.1 -> 1386000 | Q9: =N9-P9 -> 0 | R9: O | T9: =IF(OR(I9="타이어",I9=""),"",C9) | U9: =IF(T9="","","완료")
B10: =B9+1 -> 6 | C10: 45756 | D10: =IF((C10=""),"",(YEAR(C10)&"년")) -> 2025년 | E10: =IF((C10=""),"",(MONTH(C10)&"월")) -> 4월 | F10: =CONCATENATE(D10,E10) -> 2025년4월 | G10: 도화중기주식회사 | H10: =IFERROR((VLOOKUP(G10,Backdata!G:H,2,0)),"") -> 301-86-32786 | I10: 타이어 | J10: 흥아 | K10: 825-15 | L10: 6 | M10: 13000 | N10: =M10*L10*1.1 -> 85800 | O10: 13000 | P10: =O10*L10*1.1 -> 85800 | Q10: =N10-P10 -> 0 | R10: O | T10: =IF(OR(I10="타이어",I10=""),"",C10) | U10: =IF(T10="","","완료")
B11: =B10+1 -> 7 | C11: 45756 | D11: =IF((C11=""),"",(YEAR(C11)&"년")) -> 2025년 | E11: =IF((C11=""),"",(MONTH(C11)&"월")) -> 4월 | F11: =CONCATENATE(D11,E11) -> 2025년4월 | G11: 도화중기주식회사 | H11: =IFERROR((VLOOKUP(G11,Backdata!G:H,2,0)),"") -> 301-86-32786 | I11: 타이어 | J11: 흥아 | K11: 825-15 | L11: 6 | M11: 8000 | N11: =M11*L11*1.1 -> 52800 | O11: 8000 | P11: =O11*L11*1.1 -> 52800 | Q11: =N11-P11 -> 0 | R11: O | T11: =IF(OR(I11="타이어",I11=""),"",C11) | U11: =IF(T11="","","완료")
B12: =B11+1 -> 8 | C12: 45757 | D12: =IF((C12=""),"",(YEAR(C12)&"년")) -> 2025년 | E12: =IF((C12=""),"",(MONTH(C12)&"월")) -> 4월 | F12: =CONCATENATE(D12,E12) -> 2025년4월 | G12: 에코파밍 주식회사 | H12: =IFERROR((VLOOKUP(G12,Backdata!G:H,2,0)),"") -> 318-81-11047 | I12: 렌탈 | J12: BYD | K12: 3톤 | L12: 1 | M12: 630000 | N12: =M12*L12*1.1 -> 693000 | O12: 580000 | P12: =O12*L12*1.1 -> 638000 | Q12: =N12-P12 -> 55000 | R12: O | T12: =IF(OR(I12="타이어",I12=""),"",C12) -> 45757 | U12: =IF(T12="","","완료") -> 완료
B13: =B12+1 -> 9 | C13: 45758 | D13: =IF((C13=""),"",(YEAR(C13)&"년")) -> 2025년 | E13: =IF((C13=""),"",(MONTH(C13)&"월")) -> 4월 | F13: =CONCATENATE(D13,E13) -> 2025년4월 | G13: 상주대형중기화물 | H13: =IFERROR((VLOOKUP(G13,Backdata!G:H,2,0)),"") -> 508-03-62404 | I13: 타이어 | J13: KENEX | K13: 650-10 | L13: 10 | M13: 99000 | N13: =M13*L13*1.1 -> 1089000 | O13: 85000 | P13: =O13*L13*1.1 -> 935000 | Q13: =N13-P13 -> 154000 | R13: O | T13: =IF(OR(I13="타이어",I13=""),"",C13) | U13: =IF(T13="","","완료")
B14: =B13+1 -> 10 | C14: 45758 | D14: =IF((C14=""),"",(YEAR(C14)&"년")) -> 2025년 | E14: =IF((C14=""),"",(MONTH(C14)&"월")) -> 4월 | F14: =CONCATENATE(D14,E14) -> 2025년4월 | G14: 상주대형중기화물 | H14: =IFERROR((VLOOKUP(G14,Backdata!G:H,2,0)),"") -> 508-03-62404 | I14: 타이어 | J14: KENEX | K14: 815-15 | L14: 4 | M14: 214000 | N14: =M14*L14*1.1 -> 941600 | O14: 190000 | P14: =O14*L14*1.1 -> 836000 | Q14: =N14-P14 -> 105600 | R14: O | T14: =IF(OR(I14="타이어",I14=""),"",C14) | U14: =IF(T14="","","완료")
B15: =B14+1 -> 11 | C15: 45758 | D15: =IF((C15=""),"",(YEAR(C15)&"년")) -> 2025년 | E15: =IF((C15=""),"",(MONTH(C15)&"월")) -> 4월 | F15: =CONCATENATE(D15,E15) -> 2025년4월 | G15: 상주대형중기화물 | H15: =IFERROR((VLOOKUP(G15,Backdata!G:H,2,0)),"") -> 508-03-62404 | I15: 타이어 | J15: 금호타이어 | K15: 600-15 | L15: 4 | M15: 185000 | N15: =M15*L15*1.1 -> 814000 | O15: 170000 | P15: =O15*L15*1.1 -> 748000 | Q15: =N15-P15 -> 66000 | R15: O | T15: =IF(OR(I15="타이어",I15=""),"",C15) | U15: =IF(T15="","","완료")
B16: =B15+1 -> 12 | C16: 45758 | D16: =IF((C16=""),"",(YEAR(C16)&"년")) -> 2025년 | E16: =IF((C16=""),"",(MONTH(C16)&"월")) -> 4월 | F16: =CONCATENATE(D16,E16) -> 2025년4월 | G16: 상주대형중기화물 | H16: =IFERROR((VLOOKUP(G16,Backdata!G:H,2,0)),"") -> 508-03-62404 | I16: 타이어 | J16: 금호타이어 | K16: 600-15 | L16: 4 | M16: 28000 | N16: =M16*L16*1.1 -> 123200 | O16: 25000 | P16: =O16*L16*1.1 -> 110000 | Q16: =N16-P16 -> 13200 | R16: O | T16: =IF(OR(I16="타이어",I16=""),"",C16) | U16: =IF(T16="","","완료")
B17: =B16+1 -> 13 | C17: 45779 | D17: =IF((C17=""),"",(YEAR(C17)&"년")) -> 2025년 | E17: =IF((C17=""),"",(MONTH(C17)&"월")) -> 5월 | F17: =CONCATENATE(D17,E17) -> 2025년5월 | G17: 동성종합지게차 | H17: =IFERROR((VLOOKUP(G17,Backdata!G:H,2,0)),"") -> 622-09-69331 | I17: 기타 | J17: BYD | K17: 3톤 | L17: 6 | M17: 10000000 | N17: =M17*L17*1.1 -> 66000000 | O17: 8000000 | P17: =O17*L17*1.1 -> 52800000 | Q17: =N17-P17 -> 13200000 | R17: O | T17: =IF(OR(I17="타이어",I17=""),"",C17) -> 45779 | U17: =IF(T17="","","완료") -> 완료
B18: =B17+1 -> 14 | C18: 45784 | D18: =IF((C18=""),"",(YEAR(C18)&"년")) -> 2025년 | E18: =IF((C18=""),"",(MONTH(C18)&"월")) -> 5월 | F18: =CONCATENATE(D18,E18) -> 2025년5월 | G18: 에코파밍 주식회사 | H18: =IFERROR((VLOOKUP(G18,Backdata!G:H,2,0)),"") -> 318-81-11047 | I18: 렌탈 | J18: BYD | K18: 2.5톤 | L18: 1 | M18: 630000 | N18: =M18*L18*1.1 -> 693000 | O18: 580000 | P18: =O18*L18*1.1 -> 638000 | Q18: =N18-P18 -> 55000 | R18: O | T18: =IF(OR(I18="타이어",I18=""),"",C18) -> 45784 | U18: =IF(T18="","","완료") -> 완료
... B28: =B27+1 -> 24 | C28: 45792 | D28: =IF((C28=""),"",(YEAR(C28)&"년")) -> 2025년 | E28: =IF((C28=""),"",(MONTH(C28)&"월")) -> 5월 | F28: =CONCATENATE(D28,E28) -> 2025년5월 | G28: 도화중기주식회사 | H28: =IFERROR((VLOOKUP(G28,Backdata!G:H,2,0)),"") -> 301-86-32786 | I28: 타이어 | J28: 휠 | K28: 900-20 | L28: 1 | M28: 250000 | N28: =M28*L28*1.1 -> 275000 | O28: 230000 | P28: =O28*L28*1.1 -> 253000 | Q28: =N28-P28 -> 22000 | R28: O | T28: =IF(OR(I28="타이어",I28=""),"",C28) | U28: =IF(T28="","","완료")
B29: =B28+1 -> 25 | C29: 45793 | D29: =IF((C29=""),"",(YEAR(C29)&"년")) -> 2025년 | E29: =IF((C29=""),"",(MONTH(C29)&"월")) -> 5월 | F29: =CONCATENATE(D29,E29) -> 2025년5월 | G29: 현대지게차경기북부판매(주) | H29: =IFERROR((VLOOKUP(G29,Backdata!G:H,2,0)),"") -> 428-86-01083 | I29: 기타 | J29: 현대 | K29: 3톤 | L29: 2 | M29: 1000000 | N29: =M29*L29*1.1 -> 2200000 | P29: =O29*L29*1.1 -> 0 | Q29: =N29-P29 -> 2200000 | R29: O | T29: =IF(OR(I29="타이어",I29=""),"",C29) -> 45793 | U29: =IF(T29="","","완료") -> 완료
B30: =B29+1 -> 26 | C30: 45793 | D30: =IF((C30=""),"",(YEAR(C30)&"년")) -> 2025년 | E30: =IF((C30=""),"",(MONTH(C30)&"월")) -> 5월 | F30: =CONCATENATE(D30,E30) -> 2025년5월 | G30: 주식회사 에스제이 | H30: =IFERROR((VLOOKUP(G30,Backdata!G:H,2,0)),"") -> 235-86-01235 | I30: 렌탈 | J30: 현대 | K30: 3톤 | L30: 2 | M30: 1100000 | N30: =M30*L30*1.1 -> 2420000 | O30: 800000 | P30: =O30*L30*1.1 -> 1760000 | Q30: =N30-P30 -> 660000 | R30: O | T30: =IF(OR(I30="타이어",I30=""),"",C30) -> 45793 | U30: =IF(T30="","","완료") -> 완료
B31: =B30+1 -> 27 | C31: 45797 | D31: =IF((C31=""),"",(YEAR(C31)&"년")) -> 2025년 | E31: =IF((C31=""),"",(MONTH(C31)&"월")) -> 5월 | F31: =CONCATENATE(D31,E31) -> 2025년5월 | G31: (주)디피엘 | H31: =IFERROR((VLOOKUP(G31,Backdata!G:H,2,0)),"") -> 126-81-12016 | I31: 타이어 | J31: MAXAM | K31: 21*8-9 | L31: 2 | M31: 175000 | N31: =M31*L31*1.1 -> 385000 | O31: 160000 | P31: =O31*L31*1.1 -> 352000 | Q31: =N31-P31 -> 33000 | R31: O | T31: =IF(OR(I31="타이어",I31=""),"",C31) | U31: =IF(T31="","","완료")
B32: =B31+1 -> 28 | C32: 45797 | D32: =IF((C32=""),"",(YEAR(C32)&"년")) -> 2025년 | E32: =IF((C32=""),"",(MONTH(C32)&"월")) -> 5월 | F32: =CONCATENATE(D32,E32) -> 2025년5월 | G32: (주)디피엘 | H32: =IFERROR((VLOOKUP(G32,Backdata!G:H,2,0)),"") -> 126-81-12016 | I32: 타이어 | J32: MAXAM | K32: 18*7-8 | L32: 2 | M32: 113000 | N32: =M32*L32*1.1 -> 248600 | O32: 100000 | P32: =O32*L32*1.1 -> 220000 | Q32: =N32-P32 -> 28600 | R32: O | T32: =IF(OR(I32="타이어",I32=""),"",C32) | U32: =IF(T32="","","완료")
B33: =B32+1 -> 29 | C33: 45799 | D33: =IF((C33=""),"",(YEAR(C33)&"년")) -> 2025년 | E33: =IF((C33=""),"",(MONTH(C33)&"월")) -> 5월 | F33: =CONCATENATE(D33,E33) -> 2025년5월 | G33: 도화중기주식회사 | H33: =IFERROR((VLOOKUP(G33,Backdata!G:H,2,0)),"") -> 301-86-32786 | I33: 타이어 | J33: MAXAM | K33: 815-15 | L33: 2 | M33: 310000 | N33: =M33*L33*1.1 -> 682000 | O33: 270000 | P33: =O33*L33*1.1 -> 594000 | Q33: =N33-P33 -> 88000 | R33: O | T33: =IF(OR(I33="타이어",I33=""),"",C33) | U33: =IF(T33="","","완료")
B34: =B33+1 -> 30 | C34: 45799 | D34: =IF((C34=""),"",(YEAR(C34)&"년")) -> 2025년 | E34: =IF((C34=""),"",(MONTH(C34)&"월")) -> 5월 | F34: =CONCATENATE(D34,E34) -> 2025년5월 | G34: 현대지게차경기북부판매(주) | H34: =IFERROR((VLOOKUP(G34,Backdata!G:H,2,0)),"") -> 428-86-01083 | I34: 타이어 | J34: MAXAM | K34: 650-10 | L34: 8 | M34: 200000 | N34: =M34*L34*1.1 -> 1760000 | O34: 160000 | P34: =O34*L34*1.1 -> 1408000 | Q34: =N34-P34 -> 352000 | R34: O | T34: =IF(OR(I34="타이어",I34=""),"",C34) | U34: =IF(T34="","","완료")
B35: =B34+1 -> 31 | C35: 45799 | D35: =IF((C35=""),"",(YEAR(C35)&"년")) -> 2025년 | E35: =IF((C35=""),"",(MONTH(C35)&"월")) -> 5월 | F35: =CONCATENATE(D35,E35) -> 2025년5월 | G35: 현대지게차경기북부판매(주) | H35: =IFERROR((VLOOKUP(G35,Backdata!G:H,2,0)),"") -> 428-86-01083 | I35: 타이어 | J35: 흥아 | K35: 815-15 | L35: 2 | M35: 250000 | N35: =M35*L35*1.1 -> 550000 | O35: 225000 | P35: =O35*L35*1.1 -> 495000 | Q35: =N35-P35 -> 55000 | R35: O | T35: =IF(OR(I35="타이어",I35=""),"",C35) | U35: =IF(T35="","","완료")
B36: =B35+1 -> 32 | C36: 45799 | D36: =IF((C36=""),"",(YEAR(C36)&"년")) -> 2025년 | E36: =IF((C36=""),"",(MONTH(C36)&"월")) -> 5월 | F36: =CONCATENATE(D36,E36) -> 2025년5월 | G36: 현대지게차경기북부판매(주) | H36: =IFERROR((VLOOKUP(G36,Backdata!G:H,2,0)),"") -> 428-86-01083 | I36: 타이어 | J36: 흥아 | K36: 750-15 | L36: 4 | M36: 235000 | N36: =M36*L36*1.1 -> 1034000 | O36: 220000 | P36: =O36*L36*1.1 -> 968000 | Q36: =N36-P36 -> 66000 | R36: O | T36: =IF(OR(I36="타이어",I36=""),"",C36) | U36: =IF(T36="","","완료")
B37: =B36+1 -> 33 | C37: 45799 | D37: =IF((C37=""),"",(YEAR(C37)&"년")) -> 2025년 | E37: =IF((C37=""),"",(MONTH(C37)&"월")) -> 5월 | F37: =CONCATENATE(D37,E37) -> 2025년5월 | G37: 현대지게차경기북부판매(주) | H37: =IFERROR((VLOOKUP(G37,Backdata!G:H,2,0)),"") -> 428-86-01083 | I37: 타이어 | J37: 휠 | K37: 750-15 | L37: 4 | M37: 170000 | N37: =M37*L37*1.1 -> 748000 | O37: 150000 | P37: =O37*L37*1.1 -> 660000 | Q37: =N37-P37 -> 88000 | R37: O | T37: =IF(OR(I37="타이어",I37=""),"",C37) | U37: =IF(T37="","","완료")
B38: =B37+1 -> 34 | C38: 45799 | D38: =IF((C38=""),"",(YEAR(C38)&"년")) -> 2025년 | E38: =IF((C38=""),"",(MONTH(C38)&"월")) -> 5월 | F38: =CONCATENATE(D38,E38) -> 2025년5월 | G38: 현대지게차경기북부판매(주) | H38: =IFERROR((VLOOKUP(G38,Backdata!G:H,2,0)),"") -> 428-86-01083 | I38: 타이어 | J38: 어드밴스 | K38: 650-10 | L38: -8 | M38: 50000 | N38: =M38*L38*1.1 -> -440000 | O38: 50000 | P38: =O38*L38*1.1 -> -440000 | Q38: =N38-P38 -> 0 | R38: O | T38: =IF(OR(I38="타이어",I38=""),"",C38) | U38: =IF(T38="","","완료")
B39: =B38+1 -> 35 | C39: 45799 | D39: =IF((C39=""),"",(YEAR(C39)&"년")) -> 2025년 | E39: =IF((C39=""),"",(MONTH(C39)&"월")) -> 5월 | F39: =CONCATENATE(D39,E39) -> 2025년5월 | G39: 현대지게차경기북부판매(주) | H39: =IFERROR((VLOOKUP(G39,Backdata!G:H,2,0)),"") -> 428-86-01083 | I39: 타이어 | J39: 솔리드프로 | K39: 815-15 | L39: -2 | M39: 240000 | N39: =M39*L39*1.1 -> -528000 | O39: 240000 | P39: =O39*L39*1.1 -> -528000 | Q39: =N39-P39 -> 0 | R39: O | T39: =IF(OR(I39="타이어",I39=""),"",C39) | U39: =IF(T39="","","완료")
B40: =B39+1 -> 36 | C40: 45804 | D40: =IF((C40=""),"",(YEAR(C40)&"년")) -> 2025년 | E40: =IF((C40=""),"",(MONTH(C40)&"월")) -> 5월 | F40: =CONCATENATE(D40,E40) -> 2025년5월 | G40: 도화중기주식회사 | H40: =IFERROR((VLOOKUP(G40,Backdata!G:H,2,0)),"") -> 301-86-32786 | I40: 타이어 | J40: 흥아 | K40: 825-15 | L40: 6 | M40: 238000 | N40: =M40*L40*1.1 -> 1570800 | O40: 210000 | P40: =O40*L40*1.1 -> 1386000 | Q40: =N40-P40 -> 184800 | R40: O | T40: =IF(OR(I40="타이어",I40=""),"",C40) | U40: =IF(T40="","","완료")
B41: =B40+1 -> 37 | C41: 45805 | D41: =IF((C41=""),"",(YEAR(C41)&"년")) -> 2025년 | E41: =IF((C41=""),"",(MONTH(C41)&"월")) -> 5월 | F41: =CONCATENATE(D41,E41) -> 2025년5월 | G41: 현대지게차경기북부판매(주) | H41: =IFERROR((VLOOKUP(G41,Backdata!G:H,2,0)),"") -> 428-86-01083 | I41: 타이어 | J41: 월드스톤 | K41: 700-12 | L41: 2 | M41: 240000 | N41: =M41*L41*1.1 -> 528000 | O41: 220000 | P41: =O41*L41*1.1 -> 484000 | Q41: =N41-P41 -> 44000 | R41: O | T41: =IF(OR(I41="타이어",I41=""),"",C41) | U41: =IF(T41="","","완료")
... B63: =B62+1 -> 59 | C63: 45826 | D63: =IF((C63=""),"",(YEAR(C63)&"년")) -> 2025년 | E63: =IF((C63=""),"",(MONTH(C63)&"월")) -> 6월 | F63: =CONCATENATE(D63,E63) -> 2025년6월 | G63: 주식회사 크린어스 | H63: =IFERROR((VLOOKUP(G63,Backdata!G:H,2,0)),"") -> 138-81-32669 | I63: LFP(지게차) | J63: Spiderway | K63: 51.2V150Ah | L63: 1 | M63: 3560000 | N63: =M63*L63*1.1 -> 3916000 | O63: 3200000 | P63: =O63*L63*1.1 -> 3520000 | Q63: =N63-P63 -> 396000 | R63: O | T63: =IF(OR(I63="타이어",I63=""),"",C63) -> 45826 | U63: =IF(T63="","","완료") -> 완료
B64: =B63+1 -> 60 | C64: 45827 | D64: =IF((C64=""),"",(YEAR(C64)&"년")) -> 2025년 | E64: =IF((C64=""),"",(MONTH(C64)&"월")) -> 6월 | F64: =CONCATENATE(D64,E64) -> 2025년6월 | G64: 코오롱글로벌(주)상사부문 | H64: =IFERROR((VLOOKUP(G64,Backdata!G:H,2,0)),"") -> 119-85-35038 | I64: 기타 | J64: BYD | K64: 4톤 | L64: 1 | M64: 15500000 | N64: =M64*L64*1.1 -> 17050000 | P64: =O64*L64*1.1 -> 0 | Q64: =N64-P64 -> 17050000 | R64: O | T64: =IF(OR(I64="타이어",I64=""),"",C64) -> 45827 | U64: =IF(T64="","","완료") -> 완료
B65: =B64+1 -> 61 | C65: 45832 | D65: =IF((C65=""),"",(YEAR(C65)&"년")) -> 2025년 | E65: =IF((C65=""),"",(MONTH(C65)&"월")) -> 6월 | F65: =CONCATENATE(D65,E65) -> 2025년6월 | G65: 현대지게차경기북부판매(주) | H65: =IFERROR((VLOOKUP(G65,Backdata!G:H,2,0)),"") -> 428-86-01083 | I65: 타이어 | J65: 더블코인 | K65: 750-15 | L65: 4 | M65: 270000 | N65: =M65*L65*1.1 -> 1188000 | O65: 250000 | P65: =O65*L65*1.1 -> 1100000 | Q65: =N65-P65 -> 88000 | R65: O | T65: =IF(OR(I65="타이어",I65=""),"",C65) | U65: =IF(T65="","","완료")
B66: =B65+1 -> 62 | C66: 45833 | D66: =IF((C66=""),"",(YEAR(C66)&"년")) -> 2025년 | E66: =IF((C66=""),"",(MONTH(C66)&"월")) -> 6월 | F66: =CONCATENATE(D66,E66) -> 2025년6월 | G66: 백호중기 | H66: =IFERROR((VLOOKUP(G66,Backdata!G:H,2,0)),"") -> 134-12-98663 | I66: 타이어 | J66: 컨티넨탈 | K66: 250-15 | L66: 2 | M66: 600000 | N66: =M66*L66*1.1 -> 1320000 | O66: 500000 | P66: =O66*L66*1.1 -> 1100000 | Q66: =N66-P66 -> 220000 | R66: O | T66: =IF(OR(I66="타이어",I66=""),"",C66) | U66: =IF(T66="","","완료")
B67: =B66+1 -> 63 | C67: 45835 | D67: =IF((C67=""),"",(YEAR(C67)&"년")) -> 2025년 | E67: =IF((C67=""),"",(MONTH(C67)&"월")) -> 6월 | F67: =CONCATENATE(D67,E67) -> 2025년6월 | G67: 현대지게차경기북부판매(주) | H67: =IFERROR((VLOOKUP(G67,Backdata!G:H,2,0)),"") -> 428-86-01083 | I67: 타이어 | J67: 크라운 | K67: 6인치 | L67: 4 | M67: 200000 | N67: =M67*L67*1.1 -> 880000 | O67: 180000 | P67: =O67*L67*1.1 -> 792000 | Q67: =N67-P67 -> 88000 | R67: O | T67: =IF(OR(I67="타이어",I67=""),"",C67) | U67: =IF(T67="","","완료")
B68: =B67+1 -> 64 | C68: 45838 | D68: =IF((C68=""),"",(YEAR(C68)&"년")) -> 2025년 | E68: =IF((C68=""),"",(MONTH(C68)&"월")) -> 6월 | F68: =CONCATENATE(D68,E68) -> 2025년6월 | G68: 농업회사법인 주식회사 이엔푸드 | H68: =IFERROR((VLOOKUP(G68,Backdata!G:H,2,0)),"") -> 403-81-72982 | I68: 렌탈 | J68: 현대 | K68: 1.5톤 | L68: 1 | M68: 320000 | N68: =M68*L68*1.1 -> 352000 | O68: 580000 | P68: =O68*L68*1.1 -> 638000 | Q68: =N68-P68 -> -286000 | R68: O | T68: =IF(OR(I68="타이어",I68=""),"",C68) -> 45838 | U68: =IF(T68="","","완료") -> 완료
B69: =B68+1 -> 65 | C69: 45838 | D69: =IF((C69=""),"",(YEAR(C69)&"년")) -> 2025년 | E69: =IF((C69=""),"",(MONTH(C69)&"월")) -> 6월 | F69: =CONCATENATE(D69,E69) -> 2025년6월 | G69: 주식회사 에스제이 | H69: =IFERROR((VLOOKUP(G69,Backdata!G:H,2,0)),"") -> 235-86-01235 | I69: 렌탈 | J69: 현대 | K69: 3톤 | L69: 1 | M69: 1000000 | N69: =M69*L69*1.1 -> 1100000 | P69: =O69*L69*1.1 -> 0 | Q69: =N69-P69 -> 1100000 | R69: O | T69: =IF(OR(I69="타이어",I69=""),"",C69) -> 45838 | U69: =IF(T69="","","완료") -> 완료
B70: =B69+1 -> 66 | C70: 45843 | D70: =IF((C70=""),"",(YEAR(C70)&"년")) -> 2025년 | E70: =IF((C70=""),"",(MONTH(C70)&"월")) -> 7월 | F70: =CONCATENATE(D70,E70) -> 2025년7월 | G70: 주식회사 에스제이 | H70: =IFERROR((VLOOKUP(G70,Backdata!G:H,2,0)),"") -> 235-86-01235 | I70: 렌탈 | J70: 두산 | K70: 4.5톤 | L70: 1 | M70: 1450000 | N70: =M70*L70*1.1 -> 1595000 | O70: 1000000 | P70: =O70*L70*1.1 -> 1100000 | Q70: =N70-P70 -> 495000 | R70: O | T70: =IF(OR(I70="타이어",I70=""),"",C70) -> 45843 | U70: =IF(T70="","","완료") -> 완료
B71: =B70+1 -> 67 | C71: 45845 | D71: =IF((C71=""),"",(YEAR(C71)&"년")) -> 2025년 | E71: =IF((C71=""),"",(MONTH(C71)&"월")) -> 7월 | F71: =CONCATENATE(D71,E71) -> 2025년7월 | G71: 에코파밍 주식회사 | H71: =IFERROR((VLOOKUP(G71,Backdata!G:H,2,0)),"") -> 318-81-11047 | I71: 렌탈 | J71: BYD | K71: 2.5톤 | L71: 1 | M71: 630000 | N71: =M71*L71*1.1 -> 693000 | O71: 580000 | P71: =O71*L71*1.1 -> 638000 | Q71: =N71-P71 -> 55000 | R71: O | T71: =IF(OR(I71="타이어",I71=""),"",C71) -> 45845 | U71: =IF(T71="","","완료") -> 완료
B72: =B71+1 -> 68 | C72: 45846 | D72: =IF((C72=""),"",(YEAR(C72)&"년")) -> 2025년 | E72: =IF((C72=""),"",(MONTH(C72)&"월")) -> 7월 | F72: =CONCATENATE(D72,E72) -> 2025년7월 | G72: 현대지게차경기북부판매(주) | H72: =IFERROR((VLOOKUP(G72,Backdata!G:H,2,0)),"") -> 428-86-01083 | I72: 타이어 | J72: MAXAM | K72: 700-12 | L72: 2 | M72: 210000 | N72: =M72*L72*1.1 -> 462000 | O72: 200000 | P72: =O72*L72*1.1 -> 440000 | Q72: =N72-P72 -> 22000 | R72: O | T72: =IF(OR(I72="타이어",I72=""),"",C72) | U72: =IF(T72="","","완료")
B73: =B72+1 -> 69 | C73: 45846 | D73: =IF((C73=""),"",(YEAR(C73)&"년")) -> 2025년 | E73: =IF((C73=""),"",(MONTH(C73)&"월")) -> 7월 | F73: =CONCATENATE(D73,E73) -> 2025년7월 | G73: 현대지게차경기북부판매(주) | H73: =IFERROR((VLOOKUP(G73,Backdata!G:H,2,0)),"") -> 428-86-01083 | I73: 타이어 | J73: 휠 | K73: 700-12 | L73: 2 | M73: 110000 | N73: =M73*L73*1.1 -> 242000 | O73: 100000 | P73: =O73*L73*1.1 -> 220000 | Q73: =N73-P73 -> 22000 | R73: O | T73: =IF(OR(I73="타이어",I73=""),"",C73) | U73: =IF(T73="","","완료")
...

Sheet 입금현황
B2: 매출월 : | C2: 1월
B4: 매출처 (타이어) | C4: 매출액(VAT포함) | D4: 입금(Y/N) | E4: 입금일자 | F4: 입금은행 | H4: 매출처 (타이어 제외) | I4: 매출액(VAT포함) | J4: 입금(Y/N) | K4: 입금일자 | L4: 입금은행
B6: {=_xlfn.UNIQUE(_xlfn._xlws.FILTER(RAW!G:G, (RAW!E:E=C2)*(RAW!N:N>0)*(RAW!I:I="타이어"), ""))} -> #VALUE! | C6: =IFERROR((SUMIFS(RAW!N:N,RAW!G:G,입금현황!B6, RAW!E:E,입금현황!$C$49, RAW!I:I, "타이어")*1.1),"") -> 0 | H6: {=_xlfn.UNIQUE(_xlfn._xlws.FILTER(RAW!G:G, (RAW!E:E=C2)*(RAW!N:N>0)*(RAW!I:I<>"타이어"), ""))} -> 에코파밍 주식회사 | I6: =((SUMIFS(RAW!N:N,RAW!E:E,입금현황!$C$49,RAW!G:G,입금현황!H6))-(SUMIFS(RAW!N:N,RAW!E:E,입금현황!$C$49,RAW!I:I,"타이어",RAW!G:G,입금현황!H6)))*1.1 -> 762300
H7: 주식회사 에스제이
B8: 매출월 : | C8: 2월
B10: 매출처 (타이어) | C10: 매출액(VAT포함) | D10: 입금(Y/N) | E10: 입금일자 | F10: 입금은행 | H10: 매출처 (타이어 제외) | I10: 매출액(VAT포함)
B12: {=_xlfn.UNIQUE(_xlfn._xlws.FILTER(RAW!G:G, (RAW!E:E=C8)*(RAW!N:N>0)*(RAW!I:I="타이어"), ""))} -> 혁신상사 주식회사 | C12: =IFERROR((SUMIFS(RAW!N:N,RAW!G:G,입금현황!B12, RAW!E:E,입금현황!$C$57, RAW!I:I, "타이어")*1.1),"") -> 0 | H12: {=_xlfn.UNIQUE(_xlfn._xlws.FILTER(RAW!G:G, (RAW!E:E=C8)*(RAW!N:N>0)*(RAW!I:I<>"타이어"), ""))} -> 에코파밍 주식회사 | I12: =((SUMIFS(RAW!N:N,RAW!E:E,입금현황!$C$57,RAW!G:G,입금현황!H12))-(SUMIFS(RAW!N:N,RAW!E:E,입금현황!$C$57,RAW!I:I,"타이어",RAW!G:G,입금현황!H12)))*1.1 -> 762300
B13: (주)에이치씨물류 | H13: 주식회사 에스제이
B14: 매출월 : | C14: 3월
B16: 매출처 (타이어) | C16: 매출액(VAT포함) | D16: 입금(Y/N) | E16: 입금일자 | F16: 입금은행 | H16: 매출처 (타이어 제외) | I16: 매출액(VAT포함) | J16: 입금(Y/N) | K16: 입금일자 | L16: 입금은행
B18: {=_xlfn.UNIQUE(_xlfn._xlws.FILTER(RAW!G:G, (RAW!E:E=C14)*(RAW!N:N>0)*(RAW!I:I="타이어"), ""))} -> 현대지게차경기북부판매(주) | C18: =IFERROR((SUMIFS(RAW!N:N,RAW!G:G,입금현황!B18, RAW!E:E,입금현황!$C$64, RAW!I:I, "타이어")*1.1),"") -> 1766600 | H18: {=_xlfn.UNIQUE(_xlfn._xlws.FILTER(RAW!G:G, (RAW!E:E=C14)*(RAW!N:N>0)*(RAW!I:I<>"타이어"), ""))} -> 주식회사 에스제이 | I18: =((SUMIFS(RAW!N:N,RAW!E:E,입금현황!$C$14,RAW!G:G,입금현황!H18))-(SUMIFS(RAW!N:N,RAW!E:E,입금현황!$C$14,RAW!I:I,"타이어",RAW!G:G,입금현황!H18)))*1.1 -> 1754500 | J18: Y
C19: =IFERROR((SUMIFS(RAW!N:N,RAW!G:G,입금현황!B19, RAW!E:E,입금현황!$C$64, RAW!I:I, "타이어")*1.1),"") -> 0 | H19: 코오롱글로벌(주)상사부문 | I19: =((SUMIFS(RAW!N:N,RAW!E:E,입금현황!$C$14,RAW!G:G,입금현황!H19))-(SUMIFS(RAW!N:N,RAW!E:E,입금현황!$C$14,RAW!I:I,"타이어",RAW!G:G,입금현황!H19)))*1.1 -> 3630000 | J19: Y
H20: 에코파밍 주식회사
B21: 매출월 : | C21: 4월
B23: 매출처 (타이어) | C23: 매출액(VAT포함) | D23: 입금(Y/N) | E23: 입금일자 | F23: 입금은행 | H23: 매출처 (타이어 제외) | I23: 매출액(VAT포함) | J23: 입금(Y/N) | K23: 입금일자 | L23: 입금은행
B25: {=_xlfn.UNIQUE(_xlfn._xlws.FILTER(RAW!G:G, (RAW!E:E=C21)*(RAW!N:N>0)*(RAW!I:I="타이어"), ""))} -> 도화중기주식회사 | C25: =IFERROR((SUMIFS(RAW!N:N,RAW!G:G,입금현황!B25, RAW!E:E,입금현황!$C$21, RAW!I:I, "타이어")*1.1),"") -> 2458720 | D25: Y | H25: {=_xlfn.UNIQUE(_xlfn._xlws.FILTER(RAW!G:G, (RAW!E:E=C21)*(RAW!N:N>0)*(RAW!I:I<>"타이어"), ""))} -> 주식회사 에스제이 | I25: =((SUMIFS(RAW!N:N,RAW!E:E,입금현황!$C$21,RAW!G:G,입금현황!H25))-(SUMIFS(RAW!N:N,RAW!E:E,입금현황!$C$21,RAW!I:I,"타이어",RAW!G:G,입금현황!H25)))*1.1 -> 1754500 | J25: Y
B26: 상주대형중기화물 | C26: =IFERROR((SUMIFS(RAW!N:N,RAW!G:G,입금현황!B26, RAW!E:E,입금현황!$C$21, RAW!I:I, "타이어")*1.1),"") -> 3264580 | D26: Y | H26: 에코파밍 주식회사 | I26: =((SUMIFS(RAW!N:N,RAW!E:E,입금현황!$C$21,RAW!G:G,입금현황!H26))-(SUMIFS(RAW!N:N,RAW!E:E,입금현황!$C$21,RAW!I:I,"타이어",RAW!G:G,입금현황!H26)))*1.1 -> 762300 | J26: Y
B28: 매출월 : | C28: 5월
B30: 매출처 (타이어) | C30: 매출액(VAT포함) | D30: 입금(Y/N) | E30: 입금일자 | F30: 입금은행 | H30: 매출처 (타이어 제외) | I30: 매출액(VAT포함) | J30: 입금(Y/N) | K30: 입금일자 | L30: 입금은행
B32: {=_xlfn.UNIQUE(_xlfn._xlws.FILTER(RAW!G:G, (RAW!E:E=C28)*(RAW!N:N>0)*(RAW!I:I="타이어"), ""))} -> 상주대형중기화물 | C32: =IFERROR((SUMIFS(RAW!N:N,RAW!G:G,입금현황!B32, RAW!E:E,입금현황!$C$28, RAW!I:I, "타이어")*1.1),"") -> 1904540 | D32: Y | H32: {=_xlfn.UNIQUE(_xlfn._xlws.FILTER(RAW!G:G, (RAW!E:E=C28)*(RAW!N:N>0)*(RAW!I:I<>"타이어"), ""))} -> 동성종합지게차 | I32: =((SUMIFS(RAW!N:N,RAW!E:E,입금현황!$C$28,RAW!G:G,입금현황!H32))-(SUMIFS(RAW!N:N,RAW!E:E,입금현황!$C$28,RAW!I:I,"타이어",RAW!G:G,입금현황!H32)))*1.1 -> 72600000 | J32: Y
B33: 도화중기주식회사 | C33: =IFERROR((SUMIFS(RAW!N:N,RAW!G:G,입금현황!B33, RAW!E:E,입금현황!$C$28, RAW!I:I, "타이어")*1.1),"") -> 13670580 | D33: Y | H33: 에코파밍 주식회사 | I33: =((SUMIFS(RAW!N:N,RAW!E:E,입금현황!$C$28,RAW!G:G,입금현황!H33))-(SUMIFS(RAW!N:N,RAW!E:E,입금현황!$C$28,RAW!I:I,"타이어",RAW!G:G,입금현황!H33)))*1.1 -> 762300 | J33: Y
B34: (주)디피엘 | C34: =IFERROR((SUMIFS(RAW!N:N,RAW!G:G,입금현황!B34, RAW!E:E,입금현황!$C$28, RAW!I:I, "타이어")*1.1),"") -> 696960 | D34: Y | H34: 주식회사 에스제이 | I34: =((SUMIFS(RAW!N:N,RAW!E:E,입금현황!$C$28,RAW!G:G,입금현황!H34))-(SUMIFS(RAW!N:N,RAW!E:E,입금현황!$C$28,RAW!I:I,"타이어",RAW!G:G,입금현황!H34)))*1.1 -> 4416500 | J34: Y
B35: 현대지게차경기북부판매(주) | C35: =IFERROR((SUMIFS(RAW!N:N,RAW!G:G,입금현황!B35, RAW!E:E,입금현황!$C$28, RAW!I:I, "타이어")*1.1),"") -> 3751000 | D35: Y | H35: 현대지게차경기북부판매(주) | I35: =((SUMIFS(RAW!N:N,RAW!E:E,입금현황!$C$28,RAW!G:G,입금현황!H35))-(SUMIFS(RAW!N:N,RAW!E:E,입금현황!$C$28,RAW!I:I,"타이어",RAW!G:G,입금현황!H35)))*1.1 -> 2420000 | J35: Y
B36: 주식회사 현대지게차 | C36: =IFERROR((SUMIFS(RAW!N:N,RAW!G:G,입금현황!B36, RAW!E:E,입금현황!$C$28, RAW!I:I, "타이어")*1.1),"") -> 217800 | D36: Y | H36: 선호지게차 | J36: Y
B38: 매출월 : | C38: 6월
B40: 매출처 (타이어) | C40: 매출액(VAT포함) | D40: 입금(Y/N) | E40: 입금일자 | F40: 입금은행 | H40: 매출처 (타이어 제외) | I40: 매출액(VAT포함) | J40: 입금(Y/N) | K40: 입금일자 | L40: 입금은행
B42: {=_xlfn.UNIQUE(_xlfn._xlws.FILTER(RAW!G:G, (RAW!E:E=C38)*(RAW!N:N>0)*(RAW!I:I="타이어"), ""))} -> 현대지게차경기북부판매(주) | C42: =IFERROR((SUMIFS(RAW!N:N,RAW!G:G,입금현황!B42, RAW!E:E,입금현황!$C$38, RAW!I:I, "타이어")*1.1),"") -> 3726800 | D42: Y | H42: {=_xlfn.UNIQUE(_xlfn._xlws.FILTER(RAW!G:G, (RAW!E:E=C38)*(RAW!N:N>0)*(RAW!I:I<>"타이어"), ""))} -> 동성종합지게차 | I42: =((SUMIFS(RAW!N:N,RAW!E:E,입금현황!$C$38,RAW!G:G,입금현황!H42))-(SUMIFS(RAW!N:N,RAW!E:E,입금현황!$C$38,RAW!I:I,"타이어",RAW!G:G,입금현황!H42)))*1.1 -> 5592341.7 | J42: Y
B43: 도화중기주식회사 | C43: =IFERROR((SUMIFS(RAW!N:N,RAW!G:G,입금현황!B43, RAW!E:E,입금현황!$C$38, RAW!I:I, "타이어")*1.1),"") -> 2640220 | D43: Y | H43: 주식회사 에스제이 | I43: =((SUMIFS(RAW!N:N,RAW!E:E,입금현황!$C$38,RAW!G:G,입금현황!H43))-(SUMIFS(RAW!N:N,RAW!E:E,입금현황!$C$38,RAW!I:I,"타이어",RAW!G:G,입금현황!H43)))*1.1 -> 5626500 | J43: Y
B44: 동성종합지게차 | C44: =IFERROR((SUMIFS(RAW!N:N,RAW!G:G,입금현황!B44, RAW!E:E,입금현황!$C$38, RAW!I:I, "타이어")*1.1),"") -> 1827100 | D44: Y | H44: 에코파밍 주식회사 | I44: =((SUMIFS(RAW!N:N,RAW!E:E,입금현황!$C$38,RAW!G:G,입금현황!H44))-(SUMIFS(RAW!N:N,RAW!E:E,입금현황!$C$38,RAW!I:I,"타이어",RAW!G:G,입금현황!H44)))*1.1 -> 762300 | J44: Y
B45: 백호중기 | C45: =IFERROR((SUMIFS(RAW!N:N,RAW!G:G,입금현황!B45, RAW!E:E,입금현황!$C$38, RAW!I:I, "타이어")*1.1),"") -> 1452000 | D45: Y | H45: 주식회사 크린어스 | I45: =((SUMIFS(RAW!N:N,RAW!E:E,입금현황!$C$38,RAW!G:G,입금현황!H45))-(SUMIFS(RAW!N:N,RAW!E:E,입금현황!$C$38,RAW!I:I,"타이어",RAW!G:G,입금현황!H45)))*1.1 -> 4307600 | J45: Y
C46: =IFERROR((SUMIFS(RAW!N:N,RAW!G:G,입금현황!B46, RAW!E:E,입금현황!$C$89, RAW!I:I, "타이어")*1.1),"") -> 0 | H46: 코오롱글로벌(주)상사부문 | I46: =((SUMIFS(RAW!N:N,RAW!E:E,입금현황!$C$38,RAW!G:G,입금현황!H46))-(SUMIFS(RAW!N:N,RAW!E:E,입금현황!$C$38,RAW!I:I,"타이어",RAW!G:G,입금현황!H46)))*1.1 -> 18755000 | J46: Y
C47: =IFERROR((SUMIFS(RAW!N:N,RAW!G:G,입금현황!B47, RAW!E:E,입금현황!$C$89, RAW!I:I, "타이어")*1.1),"") -> 0 | H47: 농업회사법인 주식회사 이엔푸드 | I47: =((SUMIFS(RAW!N:N,RAW!E:E,입금현황!$C$38,RAW!G:G,입금현황!H47))-(SUMIFS(RAW!N:N,RAW!E:E,입금현황!$C$38,RAW!I:I,"타이어",RAW!G:G,입금현황!H47)))*1.1 -> 387200 | J47: Y
B49: 매출월 : | C49: 7월
B51: 매출처 (타이어) | C51: 매출액(VAT포함) | D51: 입금(Y/N) | E51: 입금일자 | F51: 입금은행 | H51: 매출처 (타이어 제외) | I51: 매출액(VAT포함) | J51: 입금(Y/N) | K51: 입금일자 | L51: 입금은행
B53: {=_xlfn.UNIQUE(_xlfn._xlws.FILTER(RAW!G:G, (RAW!E:E=C49)*(RAW!N:N>0)*(RAW!I:I="타이어"), ""))} -> 현대지게차경기북부판매(주) | C53: =IFERROR((SUMIFS(RAW!N:N,RAW!G:G,입금현황!B53, RAW!E:E,입금현황!$C$49, RAW!I:I, "타이어")*1.1),"") -> 5043280 | D53: Y | H53: {=_xlfn.UNIQUE(_xlfn._xlws.FILTER(RAW!G:G, (RAW!E:E=C49)*(RAW!N:N>0)*(RAW!I:I<>"타이어"), ""))} -> 주식회사 에스제이 | I53: =((SUMIFS(RAW!N:N,RAW!E:E,입금현황!$C$49,RAW!G:G,입금현황!H53))-(SUMIFS(RAW!N:N,RAW!E:E,입금현황!$C$49,RAW!I:I,"타이어",RAW!G:G,입금현황!H53)))*1.1 -> 4416500 | J53: Y
B54: 백호중기 | C54: =IFERROR((SUMIFS(RAW!N:N,RAW!G:G,입금현황!B54, RAW!E:E,입금현황!$C$49, RAW!I:I, "타이어")*1.1),"") -> 4646400 | D54: Y | H54: 에코파밍 주식회사 | I54: =((SUMIFS(RAW!N:N,RAW!E:E,입금현황!$C$49,RAW!G:G,입금현황!H54))-(SUMIFS(RAW!N:N,RAW!E:E,입금현황!$C$49,RAW!I:I,"타이어",RAW!G:G,입금현황!H54)))*1.1 -> 762300 | J54: Y
B55: 도화중기주식회사 | C55: =IFERROR((SUMIFS(RAW!N:N,RAW!G:G,입금현황!B55, RAW!E:E,입금현황!$C$49, RAW!I:I, "타이어")*1.1),"") -> 3775200 | D55: Y
B57: 매출월 : | C57: 8월
B59: 매출처 (타이어) | C59: 매출액(VAT포함) | D59: 입금(Y/N) | E59: 입금일자 | F59: 입금은행 | H59: 매출처 (타이어 제외) | I59: 매출액(VAT포함)
B61: {=_xlfn.UNIQUE(_xlfn._xlws.FILTER(RAW!G:G, (RAW!E:E=C57)*(RAW!N:N>0)*(RAW!I:I="타이어"), ""))} -> 현대지게차경기북부판매(주) | C61: =IFERROR((SUMIFS(RAW!N:N,RAW!G:G,입금현황!B61, RAW!E:E,입금현황!$C$57, RAW!I:I, "타이어")*1.1),"") -> 3496900 | D61: Y | H61: {=_xlfn.UNIQUE(_xlfn._xlws.FILTER(RAW!G:G, (RAW!E:E=C57)*(RAW!N:N>0)*(RAW!I:I<>"타이어"), ""))} -> 주식회사 에스제이 | I61: =((SUMIFS(RAW!N:N,RAW!E:E,입금현황!$C$57,RAW!G:G,입금현황!H61))-(SUMIFS(RAW!N:N,RAW!E:E,입금현황!$C$57,RAW!I:I,"타이어",RAW!G:G,입금현황!H61)))*1.1 -> 4416500 | J61: Y
...

Sheet 업체별 세부현황
D2: 혁신상사 주식회사 | E2: 12월
C4: 기준 월 | E4: =SUMIFS(RAW!N:N, RAW!G:G, $D$2, RAW!E:E, E2) -> 1595000
C6: 총 매출
C7: 타이어 매출
C8: 상위매출처

Sheet Backdata
A2: {=_xlfn.UNIQUE(_xlfn._xlws.FILTER(RAW!G3:G999, RAW!G3:G999<>""))} -> 고객명
A3: 주식회사 에스제이 | G3: 거래처등록번호 | H3: 종사업장번호 | I3: 대표자 | J3: 사업장주소 | K3: 업태 | S3: 종목
A4: 코오롱글로벌(주)상사부문 | G4: (주)디피엘 | H4: 126-81-12016 | J4: 최인석 | K4: 경기도 이천시 마장면 덕평로 831-35 | L4: 서비스(운수관련)업 | T4: 화물취급장비
A5: 도화중기주식회사 | G5: 기린지게차 | H5: 172-74-00096 | J5: 강용식 | K5: 대구광역시 서구 새방로 95 | L5: 도 | T5: 기계 및 기계부품
A6: 에코파밍 주식회사 | G6: 남영물류산업(주) | H6: 204-81-71256 | J6: 남후식,남희대 | K6: 경기도 광주시 곤지암읍 광여로 515 | L6: 건설업 | T6: 강구조물 철물,메자닌공
A7: 상주대형중기화물 | G7: 농업회사법인 주식회사 이엔푸드 | H7: 403-81-72982 | J7: 문형선 | K7: 전라북도 김제시 백산면 지평선산단5길 284 | L7: 제조업 | T7: 축산물가공식품
A8: 동성종합지게차 | G8: 대명특장 | H8: 476-46-00898 | J8: 백미림 | K8: 경상남도 창원시 진해구 남영로511번길 48(남양동) | L8: 제조업 | T8: 특장차
A9: 현대지게차경기북부판매(주) | G9: 대양토탈라인 주식회사 | H9: 502-81-47188 | J9: 곽충구 | K9: 경상북도 구미시 1공단로4길 38-19 | L9: 운수 | T9: 특수화물자동차
A10: (주)디피엘 | G10: 도화중기주식회사 | H10: 301-86-32786 | J10: 박정규 | K10: 충청북도 진천군 문백면 농다리로 34-18 | L10: 도소매 | T10: 건설기계장비부품
A11: 주식회사 현대지게차 | G11: 동성종합지게차 | H11: 622-09-69331 | J11: 김일홍 | K11: 경상남도 김해시 진영읍 죽곡리 228-1 | L11: 도매업 | T11: 기타운수및기계장비
A12: 선호지게차 | G12: 두산지게차순천판매주식회사 | H12: 416-81-34873 | J12: 김정이 | K12: 전라남도 순천시 해룡면 용전길 2 | L12: 서비스 | T12: 중장비위탁판매
A13: 주식회사 크린어스 | G13: 렌탈로114 | H13: 670-03-02604 | J13: 류종수 | K13: 대구광역시 동구 반야월북로55길 18-3(신서동, 국화빌라) 101호 | L13: 사업시설 관리, 사업지원 및 임대 서비스업 | T13: 기타 산업용 기계 및 장비 임대업
A14: 백호중기 | G14: 백호중기 | H14: 134-12-98663 | J14: 이대홍 | K14: 경기도 김포시 하성면 월하로 589번길 33 | L14: 제조업 | T14: 기타 일반 기계 및 장비 수리업
A15: 농업회사법인 주식회사 이엔푸드 | G15: 상주대형중기화물 | H15: 508-03-62404 | J15: 강미화 | K15: 경상북도 상주시 식산로96 (서곡동) | L15: 운보 | T15: 화물
... A22: (주)에이치씨물류 | G22: 주식회사 지게차나라 | H22: 142-81-55069 | J22: 최영호 | K22: 경기도 용인시 처인구 양지면 남평로 192 | L22: 도매 및 소매업 | T22: 지게차
G23: 주식회사 코지스산업 | H23: 142-81-20556 | J23: 이성준 | K23: 경기도 용인시 기흥구 흥덕1로 13 A동 2003호 (영덕동) | L23: 도소매 | T23: 전동지게차
G24: 주식회사 크린어스 | H24: 138-81-32669 | J24: 윤우용, 유영환 | K24: 경기도 용인시 기흥구 흥덕중앙로 120, 2606호 (영덕동, 유타워) | L24: 제조업 | T24: 자동조정및제어장치
G25: 주식회사 현대지게차 | H25: 125-81-82538 | J25: 최영락 | K25: 경기도 안성시 원곡면 칠곡리 512-10 | L25: 건설업 | T25: 건설기계도급및대여
G26: 천리지게차 | H26: 530-43-00298 | J26: 박노석 | K26: 대구광역시 달성군 현풍면 국가산단북로 340 | L26: 도 | T26: 물류장비,부품
G27: 캄텍주식회사 | H27: 301-81-50703 | J27: 김성근 | K27: 충청북도 진천군 이월면 고등2길 15 | L27: 제조 | T27: 자동차부품
G28: 코오롱글로벌(주)상사부문 | H28: 119-85-35038 | J28: 김정일 | K28: 경기도 과천시 코오롱로11(별양동) | L28: 도매및소매업 | T28: 상품종합도소매
G29: 티엘에스코리아 주식회사 | H29: 897-86-02385 | J29: 김하람 | K29: 충청북도 음성군 삼성면 덕정로 144번길113-74 | L29: 도뫠 및 소매업 | T29: 산업용기계
G30: 혁신상사 주식회사 | H30: 312-86-18125 | J30: 권혁봉 | K30: 충청남도 천안시 서북구 성환읍 왕림길 198-25 | L30: 제조 | T30: 지게차부품
G31: 현대지게차경기북부판매(주) | H31: 428-86-01083 | J31: 김형일 | K31: 경기도 포천시 내촌면 내진로 131 | L31: 도소매 | T31: 중기 및 부품
G32: (주)에이치씨물류 | H32: 503-81-85128 | J32: 서동묵 | K32: 대구광역시 북구 노원로 139-6, 5층(노원동3가) | L32: 운수업
